2020-06-17 02:59:57,741 — analytics_service — ERROR — Exception on /analyse/ [GET]
Traceback (most recent call last):
  File "/usr/local/lib/python3.8/site-packages/flask/app.py", line 2446, in wsgi_app
    response = self.full_dispatch_request()
  File "/usr/local/lib/python3.8/site-packages/flask/app.py", line 1952, in full_dispatch_request
    return self.finalize_request(rv)
  File "/usr/local/lib/python3.8/site-packages/flask/app.py", line 1967, in finalize_request
    response = self.make_response(rv)
  File "/usr/local/lib/python3.8/site-packages/flask/app.py", line 2126, in make_response
    raise TypeError(
TypeError: The view function did not return a valid response. The return type must be a string, dict, tuple, Response instance, or WSGI callable, but it was a list.
2020-06-17 03:00:54,511 — analytics_service — ERROR — Exception on /analyse/ [GET]
Traceback (most recent call last):
  File "/usr/local/lib/python3.8/site-packages/flask/app.py", line 2446, in wsgi_app
    response = self.full_dispatch_request()
  File "/usr/local/lib/python3.8/site-packages/flask/app.py", line 1952, in full_dispatch_request
    return self.finalize_request(rv)
  File "/usr/local/lib/python3.8/site-packages/flask/app.py", line 1967, in finalize_request
    response = self.make_response(rv)
  File "/usr/local/lib/python3.8/site-packages/flask/app.py", line 2126, in make_response
    raise TypeError(
TypeError: The view function did not return a valid response. The return type must be a string, dict, tuple, Response instance, or WSGI callable, but it was a list.
2020-06-17 03:01:01,853 — analytics_service — ERROR — Exception on /analyse/ [GET]
Traceback (most recent call last):
  File "/usr/local/lib/python3.8/site-packages/flask/app.py", line 2446, in wsgi_app
    response = self.full_dispatch_request()
  File "/usr/local/lib/python3.8/site-packages/flask/app.py", line 1952, in full_dispatch_request
    return self.finalize_request(rv)
  File "/usr/local/lib/python3.8/site-packages/flask/app.py", line 1967, in finalize_request
    response = self.make_response(rv)
  File "/usr/local/lib/python3.8/site-packages/flask/app.py", line 2126, in make_response
    raise TypeError(
TypeError: The view function did not return a valid response. The return type must be a string, dict, tuple, Response instance, or WSGI callable, but it was a list.
2020-06-17 03:01:06,318 — analytics_service — ERROR — Exception on /analyse/ [GET]
Traceback (most recent call last):
  File "/usr/local/lib/python3.8/site-packages/flask/app.py", line 2446, in wsgi_app
    response = self.full_dispatch_request()
  File "/usr/local/lib/python3.8/site-packages/flask/app.py", line 1952, in full_dispatch_request
    return self.finalize_request(rv)
  File "/usr/local/lib/python3.8/site-packages/flask/app.py", line 1967, in finalize_request
    response = self.make_response(rv)
  File "/usr/local/lib/python3.8/site-packages/flask/app.py", line 2126, in make_response
    raise TypeError(
TypeError: The view function did not return a valid response. The return type must be a string, dict, tuple, Response instance, or WSGI callable, but it was a list.
2020-06-17 03:02:02,074 — analytics_service — ERROR — Exception on /analyse/ [GET]
Traceback (most recent call last):
  File "/usr/local/lib/python3.8/site-packages/flask/app.py", line 2446, in wsgi_app
    response = self.full_dispatch_request()
  File "/usr/local/lib/python3.8/site-packages/flask/app.py", line 1952, in full_dispatch_request
    return self.finalize_request(rv)
  File "/usr/local/lib/python3.8/site-packages/flask/app.py", line 1967, in finalize_request
    response = self.make_response(rv)
  File "/usr/local/lib/python3.8/site-packages/flask/app.py", line 2126, in make_response
    raise TypeError(
TypeError: The view function did not return a valid response. The return type must be a string, dict, tuple, Response instance, or WSGI callable, but it was a list.
2020-06-17 03:03:06,767 — analytics_service — ERROR — Exception on /analyse/ [GET]
Traceback (most recent call last):
  File "/usr/local/lib/python3.8/site-packages/flask/app.py", line 2446, in wsgi_app
    response = self.full_dispatch_request()
  File "/usr/local/lib/python3.8/site-packages/flask/app.py", line 1952, in full_dispatch_request
    return self.finalize_request(rv)
  File "/usr/local/lib/python3.8/site-packages/flask/app.py", line 1967, in finalize_request
    response = self.make_response(rv)
  File "/usr/local/lib/python3.8/site-packages/flask/app.py", line 2126, in make_response
    raise TypeError(
TypeError: The view function did not return a valid response. The return type must be a string, dict, tuple, Response instance, or WSGI callable, but it was a list.
2020-06-17 03:03:40,894 — analytics_service — ERROR — Exception on /analyse/ [GET]
Traceback (most recent call last):
  File "/usr/local/lib/python3.8/site-packages/flask/app.py", line 2446, in wsgi_app
    response = self.full_dispatch_request()
  File "/usr/local/lib/python3.8/site-packages/flask/app.py", line 1952, in full_dispatch_request
    return self.finalize_request(rv)
  File "/usr/local/lib/python3.8/site-packages/flask/app.py", line 1967, in finalize_request
    response = self.make_response(rv)
  File "/usr/local/lib/python3.8/site-packages/flask/app.py", line 2126, in make_response
    raise TypeError(
TypeError: The view function did not return a valid response. The return type must be a string, dict, tuple, Response instance, or WSGI callable, but it was a list.
2020-06-17 03:04:35,717 — analytics_service — ERROR — Exception on /analyse/ [GET]
Traceback (most recent call last):
  File "/usr/local/lib/python3.8/site-packages/flask/app.py", line 2446, in wsgi_app
    response = self.full_dispatch_request()
  File "/usr/local/lib/python3.8/site-packages/flask/app.py", line 1952, in full_dispatch_request
    return self.finalize_request(rv)
  File "/usr/local/lib/python3.8/site-packages/flask/app.py", line 1967, in finalize_request
    response = self.make_response(rv)
  File "/usr/local/lib/python3.8/site-packages/flask/app.py", line 2126, in make_response
    raise TypeError(
TypeError: The view function did not return a valid response. The return type must be a string, dict, tuple, Response instance, or WSGI callable, but it was a Response.
2020-06-17 03:07:47,374 — analytics_service — ERROR — Exception on /analyse/ [GET]
Traceback (most recent call last):
  File "/usr/local/lib/python3.8/site-packages/flask/app.py", line 2446, in wsgi_app
    response = self.full_dispatch_request()
  File "/usr/local/lib/python3.8/site-packages/flask/app.py", line 1952, in full_dispatch_request
    return self.finalize_request(rv)
  File "/usr/local/lib/python3.8/site-packages/flask/app.py", line 1967, in finalize_request
    response = self.make_response(rv)
  File "/usr/local/lib/python3.8/site-packages/flask/app.py", line 2126, in make_response
    raise TypeError(
TypeError: The view function did not return a valid response. The return type must be a string, dict, tuple, Response instance, or WSGI callable, but it was a Response.
2020-06-17 03:14:52,852 — analytics_service — ERROR — Exception on /analyse/ [GET]
Traceback (most recent call last):
  File "/usr/local/lib/python3.8/site-packages/flask/app.py", line 2446, in wsgi_app
    response = self.full_dispatch_request()
  File "/usr/local/lib/python3.8/site-packages/flask/app.py", line 1951, in full_dispatch_request
    rv = self.handle_user_exception(e)
  File "/usr/local/lib/python3.8/site-packages/flask_cors/extension.py", line 161, in wrapped_function
    return cors_after_request(app.make_response(f(*args, **kwargs)))
  File "/usr/local/lib/python3.8/site-packages/flask/app.py", line 1820, in handle_user_exception
    reraise(exc_type, exc_value, tb)
  File "/usr/local/lib/python3.8/site-packages/flask/_compat.py", line 39, in reraise
    raise value
  File "/usr/local/lib/python3.8/site-packages/flask/app.py", line 1949, in full_dispatch_request
    rv = self.dispatch_request()
  File "/usr/local/lib/python3.8/site-packages/flask/app.py", line 1935, in dispatch_request
    return self.view_functions[rule.endpoint](**req.view_args)
  File "/home/sde/Desktop/projects/Egg-Shaped_Apostle/services/analytics_service/analytics_service.py", line 55, in analyse
    resp = draw_imgs(r.json()['response'])
  File "/home/sde/Desktop/projects/Egg-Shaped_Apostle/services/analytics_service/analytics_service.py", line 60, in draw_imgs
    texts = [i[5] for i in text_list]
  File "/home/sde/Desktop/projects/Egg-Shaped_Apostle/services/analytics_service/analytics_service.py", line 60, in <listcomp>
    texts = [i[5] for i in text_list]
IndexError: list index out of range
2020-06-17 03:15:25,029 — analytics_service — ERROR — Exception on /analyse/ [GET]
Traceback (most recent call last):
  File "/usr/local/lib/python3.8/site-packages/flask/app.py", line 2446, in wsgi_app
    response = self.full_dispatch_request()
  File "/usr/local/lib/python3.8/site-packages/flask/app.py", line 1951, in full_dispatch_request
    rv = self.handle_user_exception(e)
  File "/usr/local/lib/python3.8/site-packages/flask_cors/extension.py", line 161, in wrapped_function
    return cors_after_request(app.make_response(f(*args, **kwargs)))
  File "/usr/local/lib/python3.8/site-packages/flask/app.py", line 1820, in handle_user_exception
    reraise(exc_type, exc_value, tb)
  File "/usr/local/lib/python3.8/site-packages/flask/_compat.py", line 39, in reraise
    raise value
  File "/usr/local/lib/python3.8/site-packages/flask/app.py", line 1949, in full_dispatch_request
    rv = self.dispatch_request()
  File "/usr/local/lib/python3.8/site-packages/flask/app.py", line 1935, in dispatch_request
    return self.view_functions[rule.endpoint](**req.view_args)
  File "/home/sde/Desktop/projects/Egg-Shaped_Apostle/services/analytics_service/analytics_service.py", line 56, in analyse
    resp = draw_imgs(r.json()['response'])
  File "/home/sde/Desktop/projects/Egg-Shaped_Apostle/services/analytics_service/analytics_service.py", line 61, in draw_imgs
    texts = [i[5] for i in text_list]
  File "/home/sde/Desktop/projects/Egg-Shaped_Apostle/services/analytics_service/analytics_service.py", line 61, in <listcomp>
    texts = [i[5] for i in text_list]
IndexError: list index out of range
2020-06-17 03:15:48,372 — analytics_service — ERROR — Exception on /analyse/ [GET]
Traceback (most recent call last):
  File "/usr/local/lib/python3.8/site-packages/flask/app.py", line 2446, in wsgi_app
    response = self.full_dispatch_request()
  File "/usr/local/lib/python3.8/site-packages/flask/app.py", line 1951, in full_dispatch_request
    rv = self.handle_user_exception(e)
  File "/usr/local/lib/python3.8/site-packages/flask_cors/extension.py", line 161, in wrapped_function
    return cors_after_request(app.make_response(f(*args, **kwargs)))
  File "/usr/local/lib/python3.8/site-packages/flask/app.py", line 1820, in handle_user_exception
    reraise(exc_type, exc_value, tb)
  File "/usr/local/lib/python3.8/site-packages/flask/_compat.py", line 39, in reraise
    raise value
  File "/usr/local/lib/python3.8/site-packages/flask/app.py", line 1949, in full_dispatch_request
    rv = self.dispatch_request()
  File "/usr/local/lib/python3.8/site-packages/flask/app.py", line 1935, in dispatch_request
    return self.view_functions[rule.endpoint](**req.view_args)
  File "/home/sde/Desktop/projects/Egg-Shaped_Apostle/services/analytics_service/analytics_service.py", line 56, in analyse
    resp = draw_imgs(r.json()['response'])
  File "/home/sde/Desktop/projects/Egg-Shaped_Apostle/services/analytics_service/analytics_service.py", line 61, in draw_imgs
    texts = [i[5] for i in text_list]
  File "/home/sde/Desktop/projects/Egg-Shaped_Apostle/services/analytics_service/analytics_service.py", line 61, in <listcomp>
    texts = [i[5] for i in text_list]
IndexError: list index out of range
2020-06-17 03:16:41,137 — analytics_service — ERROR — Exception on /analyse/ [GET]
Traceback (most recent call last):
  File "/usr/local/lib/python3.8/site-packages/flask/app.py", line 2446, in wsgi_app
    response = self.full_dispatch_request()
  File "/usr/local/lib/python3.8/site-packages/flask/app.py", line 1952, in full_dispatch_request
    return self.finalize_request(rv)
  File "/usr/local/lib/python3.8/site-packages/flask/app.py", line 1967, in finalize_request
    response = self.make_response(rv)
  File "/usr/local/lib/python3.8/site-packages/flask/app.py", line 2126, in make_response
    raise TypeError(
TypeError: The view function did not return a valid response. The return type must be a string, dict, tuple, Response instance, or WSGI callable, but it was a list.
2020-06-17 03:17:55,991 — analytics_service — ERROR — Exception on /analyse/ [GET]
Traceback (most recent call last):
  File "/usr/local/lib/python3.8/site-packages/flask/app.py", line 2446, in wsgi_app
    response = self.full_dispatch_request()
  File "/usr/local/lib/python3.8/site-packages/flask/app.py", line 1951, in full_dispatch_request
    rv = self.handle_user_exception(e)
  File "/usr/local/lib/python3.8/site-packages/flask_cors/extension.py", line 161, in wrapped_function
    return cors_after_request(app.make_response(f(*args, **kwargs)))
  File "/usr/local/lib/python3.8/site-packages/flask/app.py", line 1820, in handle_user_exception
    reraise(exc_type, exc_value, tb)
  File "/usr/local/lib/python3.8/site-packages/flask/_compat.py", line 39, in reraise
    raise value
  File "/usr/local/lib/python3.8/site-packages/flask/app.py", line 1949, in full_dispatch_request
    rv = self.dispatch_request()
  File "/usr/local/lib/python3.8/site-packages/flask/app.py", line 1935, in dispatch_request
    return self.view_functions[rule.endpoint](**req.view_args)
  File "/home/sde/Desktop/projects/Egg-Shaped_Apostle/services/analytics_service/analytics_service.py", line 56, in analyse
    resp = draw_imgs(r.json()['response'][0])
TypeError: list indices must be integers or slices, not str
2020-06-17 03:18:28,266 — analytics_service — ERROR — Exception on /analyse/ [GET]
Traceback (most recent call last):
  File "/usr/local/lib/python3.8/site-packages/flask/app.py", line 2446, in wsgi_app
    response = self.full_dispatch_request()
  File "/usr/local/lib/python3.8/site-packages/flask/app.py", line 1951, in full_dispatch_request
    rv = self.handle_user_exception(e)
  File "/usr/local/lib/python3.8/site-packages/flask_cors/extension.py", line 161, in wrapped_function
    return cors_after_request(app.make_response(f(*args, **kwargs)))
  File "/usr/local/lib/python3.8/site-packages/flask/app.py", line 1820, in handle_user_exception
    reraise(exc_type, exc_value, tb)
  File "/usr/local/lib/python3.8/site-packages/flask/_compat.py", line 39, in reraise
    raise value
  File "/usr/local/lib/python3.8/site-packages/flask/app.py", line 1949, in full_dispatch_request
    rv = self.dispatch_request()
  File "/usr/local/lib/python3.8/site-packages/flask/app.py", line 1935, in dispatch_request
    return self.view_functions[rule.endpoint](**req.view_args)
  File "/home/sde/Desktop/projects/Egg-Shaped_Apostle/services/analytics_service/analytics_service.py", line 56, in analyse
    resp = draw_imgs(r.json()['response'][0])
TypeError: list indices must be integers or slices, not str
2020-06-17 05:09:53,673 — analytics_service — ERROR — Exception on /analyse/ [GET]
Traceback (most recent call last):
  File "/home/sde/.local/lib/python3.8/site-packages/urllib3/connection.py", line 156, in _new_conn
    conn = connection.create_connection(
  File "/home/sde/.local/lib/python3.8/site-packages/urllib3/util/connection.py", line 84, in create_connection
    raise err
  File "/home/sde/.local/lib/python3.8/site-packages/urllib3/util/connection.py", line 74, in create_connection
    sock.connect(sa)
ConnectionRefusedError: [Errno 111] Connection refused

During handling of the above exception, another exception occurred:

Traceback (most recent call last):
  File "/home/sde/.local/lib/python3.8/site-packages/urllib3/connectionpool.py", line 665, in urlopen
    httplib_response = self._make_request(
  File "/home/sde/.local/lib/python3.8/site-packages/urllib3/connectionpool.py", line 387, in _make_request
    conn.request(method, url, **httplib_request_kw)
  File "/usr/local/lib/python3.8/http/client.py", line 1230, in request
    self._send_request(method, url, body, headers, encode_chunked)
  File "/usr/local/lib/python3.8/http/client.py", line 1276, in _send_request
    self.endheaders(body, encode_chunked=encode_chunked)
  File "/usr/local/lib/python3.8/http/client.py", line 1225, in endheaders
    self._send_output(message_body, encode_chunked=encode_chunked)
  File "/usr/local/lib/python3.8/http/client.py", line 1004, in _send_output
    self.send(msg)
  File "/usr/local/lib/python3.8/http/client.py", line 944, in send
    self.connect()
  File "/home/sde/.local/lib/python3.8/site-packages/urllib3/connection.py", line 184, in connect
    conn = self._new_conn()
  File "/home/sde/.local/lib/python3.8/site-packages/urllib3/connection.py", line 168, in _new_conn
    raise NewConnectionError(
urllib3.exceptions.NewConnectionError: <urllib3.connection.HTTPConnection object at 0x7f4d1805c520>: Failed to establish a new connection: [Errno 111] Connection refused

During handling of the above exception, another exception occurred:

Traceback (most recent call last):
  File "/home/sde/.local/lib/python3.8/site-packages/requests/adapters.py", line 439, in send
    resp = conn.urlopen(
  File "/home/sde/.local/lib/python3.8/site-packages/urllib3/connectionpool.py", line 719, in urlopen
    retries = retries.increment(
  File "/home/sde/.local/lib/python3.8/site-packages/urllib3/util/retry.py", line 436, in increment
    raise MaxRetryError(_pool, url, error or ResponseError(cause))
urllib3.exceptions.MaxRetryError: HTTPConnectionPool(host='127.0.0.1', port=5730): Max retries exceeded with url: /filter (Caused by NewConnectionError('<urllib3.connection.HTTPConnection object at 0x7f4d1805c520>: Failed to establish a new connection: [Errno 111] Connection refused'))

During handling of the above exception, another exception occurred:

Traceback (most recent call last):
  File "/usr/local/lib/python3.8/site-packages/flask/app.py", line 2446, in wsgi_app
    response = self.full_dispatch_request()
  File "/usr/local/lib/python3.8/site-packages/flask/app.py", line 1951, in full_dispatch_request
    rv = self.handle_user_exception(e)
  File "/usr/local/lib/python3.8/site-packages/flask_cors/extension.py", line 161, in wrapped_function
    return cors_after_request(app.make_response(f(*args, **kwargs)))
  File "/usr/local/lib/python3.8/site-packages/flask/app.py", line 1820, in handle_user_exception
    reraise(exc_type, exc_value, tb)
  File "/usr/local/lib/python3.8/site-packages/flask/_compat.py", line 39, in reraise
    raise value
  File "/usr/local/lib/python3.8/site-packages/flask/app.py", line 1949, in full_dispatch_request
    rv = self.dispatch_request()
  File "/usr/local/lib/python3.8/site-packages/flask/app.py", line 1935, in dispatch_request
    return self.view_functions[rule.endpoint](**req.view_args)
  File "/home/sde/Desktop/projects/Egg-Shaped_Apostle/services/analytics_service/analytics_service.py", line 52, in analyse
    r = requests.get(storage_service_api + '/filter',
  File "/home/sde/.local/lib/python3.8/site-packages/requests/api.py", line 76, in get
    return request('get', url, params=params, **kwargs)
  File "/home/sde/.local/lib/python3.8/site-packages/requests/api.py", line 61, in request
    return session.request(method=method, url=url, **kwargs)
  File "/home/sde/.local/lib/python3.8/site-packages/requests/sessions.py", line 530, in request
    resp = self.send(prep, **send_kwargs)
  File "/home/sde/.local/lib/python3.8/site-packages/requests/sessions.py", line 643, in send
    r = adapter.send(request, **kwargs)
  File "/home/sde/.local/lib/python3.8/site-packages/requests/adapters.py", line 516, in send
    raise ConnectionError(e, request=request)
requests.exceptions.ConnectionError: HTTPConnectionPool(host='127.0.0.1', port=5730): Max retries exceeded with url: /filter (Caused by NewConnectionError('<urllib3.connection.HTTPConnection object at 0x7f4d1805c520>: Failed to establish a new connection: [Errno 111] Connection refused'))
